Workbook

Sheet README
A2: SUNDAY FUNDAY — LEAGUE HISTORY
A4: Sleeper league 1313676998056378368 (2019-2025) + manually curated ESPN-era records (2012-2018)
A7: Seasons covered: 2012 (founding season, ESPN) through 2025 (Sleeper). 14 seasons total.
A8: 2026 is pre-draft with no games played and is excluded from all stats.
A10: Sheets:
A11: All Seasons — every team's regular-season finish, record, points, and playoff result, every year.
A12: Season Champions — champion / runner-up / 3rd / 4th by year.
A13: Hall of Fame — career totals per manager, formula-driven from All Seasons.
A14: Your Career (thowd) — year-by-year finish for your team specifically.
A15: League Awards — luck rating, point differential, season superlatives, and manager badges.
A17: Notes on data:
A18: Champion / Runner-up / 3rd / 4th for 2019-2025 come directly from Sleeper's completed winners bracket.
... A34: dnevels8's franchise includes an earlier "Engler"-era portion per the source file's own footnote.

Sheet All Seasons
A1: Season | B1: Reg. Season Rank | C1: Manager | D1: Team Name | E1: W | F1: L | G1: Points For | H1: Playoff Result | I1: Points Against | J1: Point Diff | K1: Pyth. Win % | L1: Luck Rating | M1: Last Place?
A2: 2012 | B2: 1 | C2: peterbrune | D2: Butt Fumble | E2: 10 | F2: 2 | G2: 1510 | H2: 4th Place | I2: 1333 | J2: =G2-I2 -> 177 | K2: =G2^2.37/(G2^2.37+I2^2.37) -> 0.57333865 | L2: =(E2/(E2+F2))-K2 -> 0.25999469 | M2: =IF(B2=_xlfn.MAXIFS($B$2:$B$163,$A$2:$A$163,A2),1,0) -> 0
A3: 2012 | B3: 2 | C3: GBClark | D3: Ray Rice Elevator Party | E3: 9 | F3: 3 | G3: 1581 | H3: 3rd Place | I3: 1362 | J3: =G3-I3 -> 219 | K3: =G3^2.37/(G3^2.37+I3^2.37) -> 0.58743575 | L3: =(E3/(E3+F3))-K3 -> 0.16256425 | M3: =IF(B3=_xlfn.MAXIFS($B$2:$B$163,$A$2:$A$163,A3),1,0) -> 0
A4: 2012 | B4: 3 | C4: JPeters19 | D4: The Under Achievers | E4: 9 | F4: 3 | G4: 1523 | H4: Champion | I4: 1400 | J4: =G4-I4 -> 123 | K4: =G4^2.37/(G4^2.37+I4^2.37) -> 0.54972937 | L4: =(E4/(E4+F4))-K4 -> 0.20027063 | M4: =IF(B4=_xlfn.MAXIFS($B$2:$B$163,$A$2:$A$163,A4),1,0) -> 0
A5: 2012 | B5: 4 | C5: kdavis | D5: Team KSOD | E5: 6 | F5: 6 | G5: 1461 | H5: Runner-Up | I5: 1508 | J5: =G5-I5 -> -47 | K5: =G5^2.37/(G5^2.37+I5^2.37) -> 0.48124839 | L5: =(E5/(E5+F5))-K5 -> 0.01875161 | M5: =IF(B5=_xlfn.MAXIFS($B$2:$B$163,$A$2:$A$163,A5),1,0) -> 0
A6: 2012 | B6: 5 | C6: YungSimba | D6: Dear Kevin White People | E6: 6 | F6: 6 | G6: 1443 | H6: Missed Playoffs | I6: 1400 | J6: =G6-I6 -> 43 | K6: =G6^2.37/(G6^2.37+I6^2.37) -> 0.51791666 | L6: =(E6/(E6+F6))-K6 -> -0.017916661 | M6: =IF(B6=_xlfn.MAXIFS($B$2:$B$163,$A$2:$A$163,A6),1,0) -> 0
A7: 2012 | B7: 6 | C7: thowd | D7: I'm Diggin' This Gurley | E7: 5 | F7: 7 | G7: 1405 | H7: Missed Playoffs | I7: 1431 | J7: =G7-I7 -> -26 | K7: =G7^2.37/(G7^2.37+I7^2.37) -> 0.48913751 | L7: =(E7/(E7+F7))-K7 -> -0.072470846 | M7: =IF(B7=_xlfn.MAXIFS($B$2:$B$163,$A$2:$A$163,A7),1,0) -> 0
A8: 2012 | B8: 7 | C8: TylerKeel | D8: Jimmy Graham's Crackers | E8: 4 | F8: 8 | G8: 1370 | H8: Missed Playoffs | I8: 1477 | J8: =G8-I8 -> -107 | K8: =G8^2.37/(G8^2.37+I8^2.37) -> 0.45556023 | L8: =(E8/(E8+F8))-K8 -> -0.1222269 | M8: =IF(B8=_xlfn.MAXIFS($B$2:$B$163,$A$2:$A$163,A8),1,0) -> 0
A9: 2012 | B9: 8 | C9: assif | D9: WhoFalseStarted FML | E9: 4 | F9: 8 | G9: 1353 | H9: Missed Playoffs | I9: 1429 | J9: =G9-I9 -> -76 | K9: =G9^2.37/(G9^2.37+I9^2.37) -> 0.46766474 | L9: =(E9/(E9+F9))-K9 -> -0.13433141 | M9: =IF(B9=_xlfn.MAXIFS($B$2:$B$163,$A$2:$A$163,A9),1,0) -> 0
A10: 2012 | B10: 9 | C10: jphn744 | D10: I'm Jonesin For De Hops | E10: 4 | F10: 8 | G10: 1143 | H10: Missed Playoffs | I10: 1374 | J10: =G10-I10 -> -231 | K10: =G10^2.37/(G10^2.37+I10^2.37) -> 0.39263597 | L10: =(E10/(E10+F10))-K10 -> -0.059302633 | M10: =IF(B10=_xlfn.MAXIFS($B$2:$B$163,$A$2:$A$163,A10),1,0) -> 0
A11: 2012 | B11: 10 | C11: bcorrigan30 | D11: Chalupa Batmans | E11: 3 | F11: 9 | G11: 1322 | H11: Missed Playoffs | I11: 1397 | J11: =G11-I11 -> -75 | K11: =G11^2.37/(G11^2.37+I11^2.37) -> 0.46735158 | L11: =(E11/(E11+F11))-K11 -> -0.21735158 | M11: =IF(B11=_xlfn.MAXIFS($B$2:$B$163,$A$2:$A$163,A11),1,0) -> 1
A12: 2013 | B12: 1 | C12: YungSimba | D12: Dear Kevin White People | E12: 9 | F12: 4 | G12: 1636 | H12: Runner-Up | I12: 1455 | J12: =G12-I12 -> 181 | K12: =G12^2.37/(G12^2.37+I12^2.37) -> 0.56902605 | L12: =(E12/(E12+F12))-K12 -> 0.12328164 | M12: =IF(B12=_xlfn.MAXIFS($B$2:$B$163,$A$2:$A$163,A12),1,0) -> 0
A13: 2013 | B13: 2 | C13: jphn744 | D13: I'm Jonesin For De Hops | E13: 8 | F13: 5 | G13: 1821 | H13: Champion | I13: 1496 | J13: =G13-I13 -> 325 | K13: =G13^2.37/(G13^2.37+I13^2.37) -> 0.61441774 | L13: =(E13/(E13+F13))-K13 -> 0.00096687928 | M13: =IF(B13=_xlfn.MAXIFS($B$2:$B$163,$A$2:$A$163,A13),1,0) -> 0
... A163: 2025 | B163: 12 | C163: Keughes | D163: M.A.K.A | E163: 3 | F163: 11 | G163: 1313.34 | H163: Missed Playoffs | I163: 1610 | J163: =G163-I163 -> -296.66 | K163: =G163^2.37/(G163^2.37+I163^2.37) -> 0.38162048 | L163: =(E163/(E163+F163))-K163 -> -0.16733476 | M163: =IF(B163=_xlfn.MAXIFS($B$2:$B$163,$A$2:$A$163,A163),1,0) -> 1

Sheet Season Champions
A1: Season | B1: Champion | C1: Runner-Up | D1: 3rd Place | E1: 4th Place
A2: 2012 | B2: =INDEX('All Seasons'!$D$2:$D$163,MATCH(1,('All Seasons'!$A$2:$A$163=A2)*('All Seasons'!$H$2:$H$163="Champion"),0)) -> The Under Achievers | C2: =INDEX('All Seasons'!$D$2:$D$163,MATCH(1,('All Seasons'!$A$2:$A$163=A2)*('All Seasons'!$H$2:$H$163="Runner-Up"),0)) -> Team KSOD | D2: =INDEX('All Seasons'!$D$2:$D$163,MATCH(1,('All Seasons'!$A$2:$A$163=A2)*('All Seasons'!$H$2:$H$163="3rd Place"),0)) -> Ray Rice Elevator Party | E2: =INDEX('All Seasons'!$D$2:$D$163,MATCH(1,('All Seasons'!$A$2:$A$163=A2)*('All Seasons'!$H$2:$H$163="4th Place"),0)) -> Butt Fumble
A3: 2013 | B3: =INDEX('All Seasons'!$D$2:$D$163,MATCH(1,('All Seasons'!$A$2:$A$163=A3)*('All Seasons'!$H$2:$H$163="Champion"),0)) -> I'm Jonesin For De Hops | C3: =INDEX('All Seasons'!$D$2:$D$163,MATCH(1,('All Seasons'!$A$2:$A$163=A3)*('All Seasons'!$H$2:$H$163="Runner-Up"),0)) -> Dear Kevin White People | D3: =INDEX('All Seasons'!$D$2:$D$163,MATCH(1,('All Seasons'!$A$2:$A$163=A3)*('All Seasons'!$H$2:$H$163="3rd Place"),0)) -> Chalupa Batmans | E3: =INDEX('All Seasons'!$D$2:$D$163,MATCH(1,('All Seasons'!$A$2:$A$163=A3)*('All Seasons'!$H$2:$H$163="4th Place"),0)) -> I'm Diggin' This Gurley
A4: 2014 | B4: =INDEX('All Seasons'!$D$2:$D$163,MATCH(1,('All Seasons'!$A$2:$A$163=A4)*('All Seasons'!$H$2:$H$163="Champion"),0)) -> I'm Jonesin For De Hops | C4: =INDEX('All Seasons'!$D$2:$D$163,MATCH(1,('All Seasons'!$A$2:$A$163=A4)*('All Seasons'!$H$2:$H$163="Runner-Up"),0)) -> Team KSOD | D4: =INDEX('All Seasons'!$D$2:$D$163,MATCH(1,('All Seasons'!$A$2:$A$163=A4)*('All Seasons'!$H$2:$H$163="3rd Place"),0)) -> Chalupa Batmans | E4: =INDEX('All Seasons'!$D$2:$D$163,MATCH(1,('All Seasons'!$A$2:$A$163=A4)*('All Seasons'!$H$2:$H$163="4th Place"),0)) -> Dear Kevin White People
A5: 2015 | B5: =INDEX('All Seasons'!$D$2:$D$163,MATCH(1,('All Seasons'!$A$2:$A$163=A5)*('All Seasons'!$H$2:$H$163="Champion"),0)) -> Butt Fumble | C5: =INDEX('All Seasons'!$D$2:$D$163,MATCH(1,('All Seasons'!$A$2:$A$163=A5)*('All Seasons'!$H$2:$H$163="Runner-Up"),0)) -> I'm Jonesin For De Hops | D5: =INDEX('All Seasons'!$D$2:$D$163,MATCH(1,('All Seasons'!$A$2:$A$163=A5)*('All Seasons'!$H$2:$H$163="3rd Place"),0)) -> Down with ODB? Yeah u know me | E5: =INDEX('All Seasons'!$D$2:$D$163,MATCH(1,('All Seasons'!$A$2:$A$163=A5)*('All Seasons'!$H$2:$H$163="4th Place"),0)) -> Dear Kevin White People
A6: 2016 | B6: =INDEX('All Seasons'!$D$2:$D$163,MATCH(1,('All Seasons'!$A$2:$A$163=A6)*('All Seasons'!$H$2:$H$163="Champion"),0)) -> Butt Fumble | C6: =INDEX('All Seasons'!$D$2:$D$163,MATCH(1,('All Seasons'!$A$2:$A$163=A6)*('All Seasons'!$H$2:$H$163="Runner-Up"),0)) -> Jimmy Graham's Crackers | D6: =INDEX('All Seasons'!$D$2:$D$163,MATCH(1,('All Seasons'!$A$2:$A$163=A6)*('All Seasons'!$H$2:$H$163="3rd Place"),0)) -> WhoFalseStarted FML | E6: =INDEX('All Seasons'!$D$2:$D$163,MATCH(1,('All Seasons'!$A$2:$A$163=A6)*('All Seasons'!$H$2:$H$163="4th Place"),0)) -> Chalupa Batmans
A7: 2017 | B7: =INDEX('All Seasons'!$D$2:$D$163,MATCH(1,('All Seasons'!$A$2:$A$163=A7)*('All Seasons'!$H$2:$H$163="Champion"),0)) -> I'm Diggin' This Gurley | C7: =INDEX('All Seasons'!$D$2:$D$163,MATCH(1,('All Seasons'!$A$2:$A$163=A7)*('All Seasons'!$H$2:$H$163="Runner-Up"),0)) -> The Under Achievers | D7: =INDEX('All Seasons'!$D$2:$D$163,MATCH(1,('All Seasons'!$A$2:$A$163=A7)*('All Seasons'!$H$2:$H$163="3rd Place"),0)) -> Team KSOD | E7: =INDEX('All Seasons'!$D$2:$D$163,MATCH(1,('All Seasons'!$A$2:$A$163=A7)*('All Seasons'!$H$2:$H$163="4th Place"),0)) -> Dear Kevin White People
A8: 2018 | B8: =INDEX('All Seasons'!$D$2:$D$163,MATCH(1,('All Seasons'!$A$2:$A$163=A8)*('All Seasons'!$H$2:$H$163="Champion"),0)) -> Team KSOD | C8: =INDEX('All Seasons'!$D$2:$D$163,MATCH(1,('All Seasons'!$A$2:$A$163=A8)*('All Seasons'!$H$2:$H$163="Runner-Up"),0)) -> Butt Fumble | D8: =INDEX('All Seasons'!$D$2:$D$163,MATCH(1,('All Seasons'!$A$2:$A$163=A8)*('All Seasons'!$H$2:$H$163="3rd Place"),0)) -> Chalupa Batmans | E8: =INDEX('All Seasons'!$D$2:$D$163,MATCH(1,('All Seasons'!$A$2:$A$163=A8)*('All Seasons'!$H$2:$H$163="4th Place"),0)) -> I'm Diggin' This Gurley
A9: 2019 | B9: =INDEX('All Seasons'!$D$2:$D$163,MATCH(1,('All Seasons'!$A$2:$A$163=A9)*('All Seasons'!$H$2:$H$163="Champion"),0)) -> CAM JUju DIGGs IT!?!? | C9: =INDEX('All Seasons'!$D$2:$D$163,MATCH(1,('All Seasons'!$A$2:$A$163=A9)*('All Seasons'!$H$2:$H$163="Runner-Up"),0)) -> Multiple Goregasms | D9: =INDEX('All Seasons'!$D$2:$D$163,MATCH(1,('All Seasons'!$A$2:$A$163=A9)*('All Seasons'!$H$2:$H$163="3rd Place"),0)) -> Le'Veon on a Jet Plane | E9: =INDEX('All Seasons'!$D$2:$D$163,MATCH(1,('All Seasons'!$A$2:$A$163=A9)*('All Seasons'!$H$2:$H$163="4th Place"),0)) -> My Ball Zach Ertz
A10: 2020 | B10: =INDEX('All Seasons'!$D$2:$D$163,MATCH(1,('All Seasons'!$A$2:$A$163=A10)*('All Seasons'!$H$2:$H$163="Champion"),0)) -> Golden Tees | C10: =INDEX('All Seasons'!$D$2:$D$163,MATCH(1,('All Seasons'!$A$2:$A$163=A10)*('All Seasons'!$H$2:$H$163="Runner-Up"),0)) -> You Lockett Up! | D10: =INDEX('All Seasons'!$D$2:$D$163,MATCH(1,('All Seasons'!$A$2:$A$163=A10)*('All Seasons'!$H$2:$H$163="3rd Place"),0)) -> Pump the Drakes | E10: =INDEX('All Seasons'!$D$2:$D$163,MATCH(1,('All Seasons'!$A$2:$A$163=A10)*('All Seasons'!$H$2:$H$163="4th Place"),0)) -> KSOD
A11: 2021 | B11: =INDEX('All Seasons'!$D$2:$D$163,MATCH(1,('All Seasons'!$A$2:$A$163=A11)*('All Seasons'!$H$2:$H$163="Champion"),0)) -> Adams Family of Receivers | C11: =INDEX('All Seasons'!$D$2:$D$163,MATCH(1,('All Seasons'!$A$2:$A$163=A11)*('All Seasons'!$H$2:$H$163="Runner-Up"),0)) -> Lights, Kamara, Action! | D11: =INDEX('All Seasons'!$D$2:$D$163,MATCH(1,('All Seasons'!$A$2:$A$163=A11)*('All Seasons'!$H$2:$H$163="3rd Place"),0)) -> He Hurts Me | E11: =INDEX('All Seasons'!$D$2:$D$163,MATCH(1,('All Seasons'!$A$2:$A$163=A11)*('All Seasons'!$H$2:$H$163="4th Place"),0)) -> kdavis
A12: 2022 | B12: =INDEX('All Seasons'!$D$2:$D$163,MATCH(1,('All Seasons'!$A$2:$A$163=A12)*('All Seasons'!$H$2:$H$163="Champion"),0)) -> Kelce You Later | C12: =INDEX('All Seasons'!$D$2:$D$163,MATCH(1,('All Seasons'!$A$2:$A$163=A12)*('All Seasons'!$H$2:$H$163="Runner-Up"),0)) -> Gettin' Diggy With It | D12: =INDEX('All Seasons'!$D$2:$D$163,MATCH(1,('All Seasons'!$A$2:$A$163=A12)*('All Seasons'!$H$2:$H$163="3rd Place"),0)) -> Chubby Chasers | E12: =INDEX('All Seasons'!$D$2:$D$163,MATCH(1,('All Seasons'!$A$2:$A$163=A12)*('All Seasons'!$H$2:$H$163="4th Place"),0)) -> CDL Required
A13: 2023 | B13: =INDEX('All Seasons'!$D$2:$D$163,MATCH(1,('All Seasons'!$A$2:$A$163=A13)*('All Seasons'!$H$2:$H$163="Champion"),0)) -> Play The Fields | C13: =INDEX('All Seasons'!$D$2:$D$163,MATCH(1,('All Seasons'!$A$2:$A$163=A13)*('All Seasons'!$H$2:$H$163="Runner-Up"),0)) -> Super Ja'Marrio Brothers | D13: =INDEX('All Seasons'!$D$2:$D$163,MATCH(1,('All Seasons'!$A$2:$A$163=A13)*('All Seasons'!$H$2:$H$163="3rd Place"),0)) -> The Kelce Era | E13: =INDEX('All Seasons'!$D$2:$D$163,MATCH(1,('All Seasons'!$A$2:$A$163=A13)*('All Seasons'!$H$2:$H$163="4th Place"),0)) -> Olave it
... A15: 2025 | B15: =INDEX('All Seasons'!$D$2:$D$163,MATCH(1,('All Seasons'!$A$2:$A$163=A15)*('All Seasons'!$H$2:$H$163="Champion"),0)) -> Run CM-Sun God | C15: =INDEX('All Seasons'!$D$2:$D$163,MATCH(1,('All Seasons'!$A$2:$A$163=A15)*('All Seasons'!$H$2:$H$163="Runner-Up"),0)) -> Gettin' Jeanty With It | D15: =INDEX('All Seasons'!$D$2:$D$163,MATCH(1,('All Seasons'!$A$2:$A$163=A15)*('All Seasons'!$H$2:$H$163="3rd Place"),0)) -> CeeDeez Nuts 2.0 | E15: =INDEX('All Seasons'!$D$2:$D$163,MATCH(1,('All Seasons'!$A$2:$A$163=A15)*('All Seasons'!$H$2:$H$163="4th Place"),0)) -> Jacob's Ladder To 1st
A17: Formulas array-match manager names from All Seasons by season + playoff result (Ctrl+Shift+Enter compatible; openpyxl-recalculated).

Sheet Hall of Fame
A1: Manager | B1: Seasons Played | C1: Championships | D1: Runner-Ups | E1: 3rd Places | F1: Playoff Appearances | G1: Career W | H1: Career L | I1: Win % | J1: Career Points For
A2: GBClark | B2: =COUNTIF('All Seasons'!$C$2:$C$163,A2) -> 14 | C2: =COUNTIFS('All Seasons'!$C$2:$C$163,A2,'All Seasons'!$H$2:$H$163,"Champion") -> 0 | D2: =COUNTIFS('All Seasons'!$C$2:$C$163,A2,'All Seasons'!$H$2:$H$163,"Runner-Up") -> 0 | E2: =COUNTIFS('All Seasons'!$C$2:$C$163,A2,'All Seasons'!$H$2:$H$163,"3rd Place") -> 1 | F2: =COUNTIFS('All Seasons'!$C$2:$C$163,A2,'All Seasons'!$H$2:$H$163,"Champion")+COUNTIFS('All Seasons'!$C$2:$C$163,A2,'All Seasons'!$H$2:$H$163,"Runner-Up")+COUNTIFS('All Seasons'!$C$2:$C$163,A2,'All Seasons'!$H$2:$H$163,"3rd Place")+COUNTIFS('All Seasons'!$C$2:$C$163,A2,'All Seasons'!$H$2:$H$163,"4th Place")+COUNTIFS('All Seasons'!$C$2:$C$163,A2,'All Seasons'!$H$2:$H$163,"Made Playoffs") -> 5 | G2: =SUMIF('All Seasons'!$C$2:$C$163,A2,'All Seasons'!$E$2:$E$163) -> 88 | H2: =SUMIF('All Seasons'!$C$2:$C$163,A2,'All Seasons'!$F$2:$F$163) -> 98 | I2: =IF((G2+H2)=0,0,G2/(G2+H2)) -> 0.47311828 | J2: =SUMIF('All Seasons'!$C$2:$C$163,A2,'All Seasons'!$G$2:$G$163) -> 20930
A3: JPeters19 | B3: =COUNTIF('All Seasons'!$C$2:$C$163,A3) -> 12 | C3: =COUNTIFS('All Seasons'!$C$2:$C$163,A3,'All Seasons'!$H$2:$H$163,"Champion") -> 1 | D3: =COUNTIFS('All Seasons'!$C$2:$C$163,A3,'All Seasons'!$H$2:$H$163,"Runner-Up") -> 2 | E3: =COUNTIFS('All Seasons'!$C$2:$C$163,A3,'All Seasons'!$H$2:$H$163,"3rd Place") -> 0 | F3: =COUNTIFS('All Seasons'!$C$2:$C$163,A3,'All Seasons'!$H$2:$H$163,"Champion")+COUNTIFS('All Seasons'!$C$2:$C$163,A3,'All Seasons'!$H$2:$H$163,"Runner-Up")+COUNTIFS('All Seasons'!$C$2:$C$163,A3,'All Seasons'!$H$2:$H$163,"3rd Place")+COUNTIFS('All Seasons'!$C$2:$C$163,A3,'All Seasons'!$H$2:$H$163,"4th Place")+COUNTIFS('All Seasons'!$C$2:$C$163,A3,'All Seasons'!$H$2:$H$163,"Made Playoffs") -> 5 | G3: =SUMIF('All Seasons'!$C$2:$C$163,A3,'All Seasons'!$E$2:$E$163) -> 72 | H3: =SUMIF('All Seasons'!$C$2:$C$163,A3,'All Seasons'!$F$2:$F$163) -> 86 | I3: =IF((G3+H3)=0,0,G3/(G3+H3)) -> 0.4556962 | J3: =SUMIF('All Seasons'!$C$2:$C$163,A3,'All Seasons'!$G$2:$G$163) -> 18638.88
A4: Keughes | B4: =COUNTIF('All Seasons'!$C$2:$C$163,A4) -> 2 | C4: =COUNTIFS('All Seasons'!$C$2:$C$163,A4,'All Seasons'!$H$2:$H$163,"Champion") -> 0 | D4: =COUNTIFS('All Seasons'!$C$2:$C$163,A4,'All Seasons'!$H$2:$H$163,"Runner-Up") -> 0 | E4: =COUNTIFS('All Seasons'!$C$2:$C$163,A4,'All Seasons'!$H$2:$H$163,"3rd Place") -> 0 | F4: =COUNTIFS('All Seasons'!$C$2:$C$163,A4,'All Seasons'!$H$2:$H$163,"Champion")+COUNTIFS('All Seasons'!$C$2:$C$163,A4,'All Seasons'!$H$2:$H$163,"Runner-Up")+COUNTIFS('All Seasons'!$C$2:$C$163,A4,'All Seasons'!$H$2:$H$163,"3rd Place")+COUNTIFS('All Seasons'!$C$2:$C$163,A4,'All Seasons'!$H$2:$H$163,"4th Place")+COUNTIFS('All Seasons'!$C$2:$C$163,A4,'All Seasons'!$H$2:$H$163,"Made Playoffs") -> 1 | G4: =SUMIF('All Seasons'!$C$2:$C$163,A4,'All Seasons'!$E$2:$E$163) -> 12 | H4: =SUMIF('All Seasons'!$C$2:$C$163,A4,'All Seasons'!$F$2:$F$163) -> 16 | I4: =IF((G4+H4)=0,0,G4/(G4+H4)) -> 0.42857143 | J4: =SUMIF('All Seasons'!$C$2:$C$163,A4,'All Seasons'!$G$2:$G$163) -> 2943.28
A5: SeanOMara | B5: =COUNTIF('All Seasons'!$C$2:$C$163,A5) -> 11 | C5: =COUNTIFS('All Seasons'!$C$2:$C$163,A5,'All Seasons'!$H$2:$H$163,"Champion") -> 0 | D5: =COUNTIFS('All Seasons'!$C$2:$C$163,A5,'All Seasons'!$H$2:$H$163,"Runner-Up") -> 1 | E5: =COUNTIFS('All Seasons'!$C$2:$C$163,A5,'All Seasons'!$H$2:$H$163,"3rd Place") -> 2 | F5: =COUNTIFS('All Seasons'!$C$2:$C$163,A5,'All Seasons'!$H$2:$H$163,"Champion")+COUNTIFS('All Seasons'!$C$2:$C$163,A5,'All Seasons'!$H$2:$H$163,"Runner-Up")+COUNTIFS('All Seasons'!$C$2:$C$163,A5,'All Seasons'!$H$2:$H$163,"3rd Place")+COUNTIFS('All Seasons'!$C$2:$C$163,A5,'All Seasons'!$H$2:$H$163,"4th Place")+COUNTIFS('All Seasons'!$C$2:$C$163,A5,'All Seasons'!$H$2:$H$163,"Made Playoffs") -> 4 | G5: =SUMIF('All Seasons'!$C$2:$C$163,A5,'All Seasons'!$E$2:$E$163) -> 70 | H5: =SUMIF('All Seasons'!$C$2:$C$163,A5,'All Seasons'!$F$2:$F$163) -> 78 | I5: =IF((G5+H5)=0,0,G5/(G5+H5)) -> 0.47297297 | J5: =SUMIF('All Seasons'!$C$2:$C$163,A5,'All Seasons'!$G$2:$G$163) -> 16905.2
A6: TylerKeel | B6: =COUNTIF('All Seasons'!$C$2:$C$163,A6) -> 14 | C6: =COUNTIFS('All Seasons'!$C$2:$C$163,A6,'All Seasons'!$H$2:$H$163,"Champion") -> 0 | D6: =COUNTIFS('All Seasons'!$C$2:$C$163,A6,'All Seasons'!$H$2:$H$163,"Runner-Up") -> 1 | E6: =COUNTIFS('All Seasons'!$C$2:$C$163,A6,'All Seasons'!$H$2:$H$163,"3rd Place") -> 0 | F6: =COUNTIFS('All Seasons'!$C$2:$C$163,A6,'All Seasons'!$H$2:$H$163,"Champion")+COUNTIFS('All Seasons'!$C$2:$C$163,A6,'All Seasons'!$H$2:$H$163,"Runner-Up")+COUNTIFS('All Seasons'!$C$2:$C$163,A6,'All Seasons'!$H$2:$H$163,"3rd Place")+COUNTIFS('All Seasons'!$C$2:$C$163,A6,'All Seasons'!$H$2:$H$163,"4th Place")+COUNTIFS('All Seasons'!$C$2:$C$163,A6,'All Seasons'!$H$2:$H$163,"Made Playoffs") -> 2 | G6: =SUMIF('All Seasons'!$C$2:$C$163,A6,'All Seasons'!$E$2:$E$163) -> 71 | H6: =SUMIF('All Seasons'!$C$2:$C$163,A6,'All Seasons'!$F$2:$F$163) -> 115 | I6: =IF((G6+H6)=0,0,G6/(G6+H6)) -> 0.38172043 | J6: =SUMIF('All Seasons'!$C$2:$C$163,A6,'All Seasons'!$G$2:$G$163) -> 20895.54
A7: YungSimba | B7: =COUNTIF('All Seasons'!$C$2:$C$163,A7) -> 14 | C7: =COUNTIFS('All Seasons'!$C$2:$C$163,A7,'All Seasons'!$H$2:$H$163,"Champion") -> 0 | D7: =COUNTIFS('All Seasons'!$C$2:$C$163,A7,'All Seasons'!$H$2:$H$163,"Runner-Up") -> 1 | E7: =COUNTIFS('All Seasons'!$C$2:$C$163,A7,'All Seasons'!$H$2:$H$163,"3rd Place") -> 0 | F7: =COUNTIFS('All Seasons'!$C$2:$C$163,A7,'All Seasons'!$H$2:$H$163,"Champion")+COUNTIFS('All Seasons'!$C$2:$C$163,A7,'All Seasons'!$H$2:$H$163,"Runner-Up")+COUNTIFS('All Seasons'!$C$2:$C$163,A7,'All Seasons'!$H$2:$H$163,"3rd Place")+COUNTIFS('All Seasons'!$C$2:$C$163,A7,'All Seasons'!$H$2:$H$163,"4th Place")+COUNTIFS('All Seasons'!$C$2:$C$163,A7,'All Seasons'!$H$2:$H$163,"Made Playoffs") -> 6 | G7: =SUMIF('All Seasons'!$C$2:$C$163,A7,'All Seasons'!$E$2:$E$163) -> 98 | H7: =SUMIF('All Seasons'!$C$2:$C$163,A7,'All Seasons'!$F$2:$F$163) -> 88 | I7: =IF((G7+H7)=0,0,G7/(G7+H7)) -> 0.52688172 | J7: =SUMIF('All Seasons'!$C$2:$C$163,A7,'All Seasons'!$G$2:$G$163) -> 21533.64
A8: amenr5 | B8: =COUNTIF('All Seasons'!$C$2:$C$163,A8) -> 3 | C8: =COUNTIFS('All Seasons'!$C$2:$C$163,A8,'All Seasons'!$H$2:$H$163,"Champion") -> 0 | D8: =COUNTIFS('All Seasons'!$C$2:$C$163,A8,'All Seasons'!$H$2:$H$163,"Runner-Up") -> 0 | E8: =COUNTIFS('All Seasons'!$C$2:$C$163,A8,'All Seasons'!$H$2:$H$163,"3rd Place") -> 0 | F8: =COUNTIFS('All Seasons'!$C$2:$C$163,A8,'All Seasons'!$H$2:$H$163,"Champion")+COUNTIFS('All Seasons'!$C$2:$C$163,A8,'All Seasons'!$H$2:$H$163,"Runner-Up")+COUNTIFS('All Seasons'!$C$2:$C$163,A8,'All Seasons'!$H$2:$H$163,"3rd Place")+COUNTIFS('All Seasons'!$C$2:$C$163,A8,'All Seasons'!$H$2:$H$163,"4th Place")+COUNTIFS('All Seasons'!$C$2:$C$163,A8,'All Seasons'!$H$2:$H$163,"Made Playoffs") -> 0 | G8: =SUMIF('All Seasons'!$C$2:$C$163,A8,'All Seasons'!$E$2:$E$163) -> 17 | H8: =SUMIF('All Seasons'!$C$2:$C$163,A8,'All Seasons'!$F$2:$F$163) -> 25 | I8: =IF((G8+H8)=0,0,G8/(G8+H8)) -> 0.4047619 | J8: =SUMIF('All Seasons'!$C$2:$C$163,A8,'All Seasons'!$G$2:$G$163) -> 4623.98
A9: assif | B9: =COUNTIF('All Seasons'!$C$2:$C$163,A9) -> 11 | C9: =COUNTIFS('All Seasons'!$C$2:$C$163,A9,'All Seasons'!$H$2:$H$163,"Champion") -> 0 | D9: =COUNTIFS('All Seasons'!$C$2:$C$163,A9,'All Seasons'!$H$2:$H$163,"Runner-Up") -> 0 | E9: =COUNTIFS('All Seasons'!$C$2:$C$163,A9,'All Seasons'!$H$2:$H$163,"3rd Place") -> 1 | F9: =COUNTIFS('All Seasons'!$C$2:$C$163,A9,'All Seasons'!$H$2:$H$163,"Champion")+COUNTIFS('All Seasons'!$C$2:$C$163,A9,'All Seasons'!$H$2:$H$163,"Runner-Up")+COUNTIFS('All Seasons'!$C$2:$C$163,A9,'All Seasons'!$H$2:$H$163,"3rd Place")+COUNTIFS('All Seasons'!$C$2:$C$163,A9,'All Seasons'!$H$2:$H$163,"4th Place")+COUNTIFS('All Seasons'!$C$2:$C$163,A9,'All Seasons'!$H$2:$H$163,"Made Playoffs") -> 1 | G9: =SUMIF('All Seasons'!$C$2:$C$163,A9,'All Seasons'!$E$2:$E$163) -> 59 | H9: =SUMIF('All Seasons'!$C$2:$C$163,A9,'All Seasons'!$F$2:$F$163) -> 85 | I9: =IF((G9+H9)=0,0,G9/(G9+H9)) -> 0.40972222 | J9: =SUMIF('All Seasons'!$C$2:$C$163,A9,'All Seasons'!$G$2:$G$163) -> 16309.9
A10: bcorrigan30 | B10: =COUNTIF('All Seasons'!$C$2:$C$163,A10) -> 14 | C10: =COUNTIFS('All Seasons'!$C$2:$C$163,A10,'All Seasons'!$H$2:$H$163,"Champion") -> 0 | D10: =COUNTIFS('All Seasons'!$C$2:$C$163,A10,'All Seasons'!$H$2:$H$163,"Runner-Up") -> 1 | E10: =COUNTIFS('All Seasons'!$C$2:$C$163,A10,'All Seasons'!$H$2:$H$163,"3rd Place") -> 6 | F10: =COUNTIFS('All Seasons'!$C$2:$C$163,A10,'All Seasons'!$H$2:$H$163,"Champion")+COUNTIFS('All Seasons'!$C$2:$C$163,A10,'All Seasons'!$H$2:$H$163,"Runner-Up")+COUNTIFS('All Seasons'!$C$2:$C$163,A10,'All Seasons'!$H$2:$H$163,"3rd Place")+COUNTIFS('All Seasons'!$C$2:$C$163,A10,'All Seasons'!$H$2:$H$163,"4th Place")+COUNTIFS('All Seasons'!$C$2:$C$163,A10,'All Seasons'!$H$2:$H$163,"Made Playoffs") -> 11 | G10: =SUMIF('All Seasons'!$C$2:$C$163,A10,'All Seasons'!$E$2:$E$163) -> 103 | H10: =SUMIF('All Seasons'!$C$2:$C$163,A10,'All Seasons'!$F$2:$F$163) -> 83 | I10: =IF((G10+H10)=0,0,G10/(G10+H10)) -> 0.55376344 | J10: =SUMIF('All Seasons'!$C$2:$C$163,A10,'All Seasons'!$G$2:$G$163) -> 22158.1
A11: dnevels8 | B11: =COUNTIF('All Seasons'!$C$2:$C$163,A11) -> 11 | C11: =COUNTIFS('All Seasons'!$C$2:$C$163,A11,'All Seasons'!$H$2:$H$163,"Champion") -> 1 | D11: =COUNTIFS('All Seasons'!$C$2:$C$163,A11,'All Seasons'!$H$2:$H$163,"Runner-Up") -> 0 | E11: =COUNTIFS('All Seasons'!$C$2:$C$163,A11,'All Seasons'!$H$2:$H$163,"3rd Place") -> 0 | F11: =COUNTIFS('All Seasons'!$C$2:$C$163,A11,'All Seasons'!$H$2:$H$163,"Champion")+COUNTIFS('All Seasons'!$C$2:$C$163,A11,'All Seasons'!$H$2:$H$163,"Runner-Up")+COUNTIFS('All Seasons'!$C$2:$C$163,A11,'All Seasons'!$H$2:$H$163,"3rd Place")+COUNTIFS('All Seasons'!$C$2:$C$163,A11,'All Seasons'!$H$2:$H$163,"4th Place")+COUNTIFS('All Seasons'!$C$2:$C$163,A11,'All Seasons'!$H$2:$H$163,"Made Playoffs") -> 5 | G11: =SUMIF('All Seasons'!$C$2:$C$163,A11,'All Seasons'!$E$2:$E$163) -> 67 | H11: =SUMIF('All Seasons'!$C$2:$C$163,A11,'All Seasons'!$F$2:$F$163) -> 81 | I11: =IF((G11+H11)=0,0,G11/(G11+H11)) -> 0.4527027 | J11: =SUMIF('All Seasons'!$C$2:$C$163,A11,'All Seasons'!$G$2:$G$163) -> 16876.88
A12: jphn744 | B12: =COUNTIF('All Seasons'!$C$2:$C$163,A12) -> 14 | C12: =COUNTIFS('All Seasons'!$C$2:$C$163,A12,'All Seasons'!$H$2:$H$163,"Champion") -> 5 | D12: =COUNTIFS('All Seasons'!$C$2:$C$163,A12,'All Seasons'!$H$2:$H$163,"Runner-Up") -> 2 | E12: =COUNTIFS('All Seasons'!$C$2:$C$163,A12,'All Seasons'!$H$2:$H$163,"3rd Place") -> 0 | F12: =COUNTIFS('All Seasons'!$C$2:$C$163,A12,'All Seasons'!$H$2:$H$163,"Champion")+COUNTIFS('All Seasons'!$C$2:$C$163,A12,'All Seasons'!$H$2:$H$163,"Runner-Up")+COUNTIFS('All Seasons'!$C$2:$C$163,A12,'All Seasons'!$H$2:$H$163,"3rd Place")+COUNTIFS('All Seasons'!$C$2:$C$163,A12,'All Seasons'!$H$2:$H$163,"4th Place")+COUNTIFS('All Seasons'!$C$2:$C$163,A12,'All Seasons'!$H$2:$H$163,"Made Playoffs") -> 10 | G12: =SUMIF('All Seasons'!$C$2:$C$163,A12,'All Seasons'!$E$2:$E$163) -> 102 | H12: =SUMIF('All Seasons'!$C$2:$C$163,A12,'All Seasons'!$F$2:$F$163) -> 84 | I12: =IF((G12+H12)=0,0,G12/(G12+H12)) -> 0.5483871 | J12: =SUMIF('All Seasons'!$C$2:$C$163,A12,'All Seasons'!$G$2:$G$163) -> 22898.4
A13: kdavis | B13: =COUNTIF('All Seasons'!$C$2:$C$163,A13) -> 14 | C13: =COUNTIFS('All Seasons'!$C$2:$C$163,A13,'All Seasons'!$H$2:$H$163,"Champion") -> 2 | D13: =COUNTIFS('All Seasons'!$C$2:$C$163,A13,'All Seasons'!$H$2:$H$163,"Runner-Up") -> 2 | E13: =COUNTIFS('All Seasons'!$C$2:$C$163,A13,'All Seasons'!$H$2:$H$163,"3rd Place") -> 2 | F13: =COUNTIFS('All Seasons'!$C$2:$C$163,A13,'All Seasons'!$H$2:$H$163,"Champion")+COUNTIFS('All Seasons'!$C$2:$C$163,A13,'All Seasons'!$H$2:$H$163,"Runner-Up")+COUNTIFS('All Seasons'!$C$2:$C$163,A13,'All Seasons'!$H$2:$H$163,"3rd Place")+COUNTIFS('All Seasons'!$C$2:$C$163,A13,'All Seasons'!$H$2:$H$163,"4th Place")+COUNTIFS('All Seasons'!$C$2:$C$163,A13,'All Seasons'!$H$2:$H$163,"Made Playoffs") -> 12 | G13: =SUMIF('All Seasons'!$C$2:$C$163,A13,'All Seasons'!$E$2:$E$163) -> 116 | H13: =SUMIF('All Seasons'!$C$2:$C$163,A13,'All Seasons'!$F$2:$F$163) -> 70 | I13: =IF((G13+H13)=0,0,G13/(G13+H13)) -> 0.62365591 | J13: =SUMIF('All Seasons'!$C$2:$C$163,A13,'All Seasons'!$G$2:$G$163) -> 23226.92
... A15: thowd | B15: =COUNTIF('All Seasons'!$C$2:$C$163,A15) -> 14 | C15: =COUNTIFS('All Seasons'!$C$2:$C$163,A15,'All Seasons'!$H$2:$H$163,"Champion") -> 3 | D15: =COUNTIFS('All Seasons'!$C$2:$C$163,A15,'All Seasons'!$H$2:$H$163,"Runner-Up") -> 1 | E15: =COUNTIFS('All Seasons'!$C$2:$C$163,A15,'All Seasons'!$H$2:$H$163,"3rd Place") -> 1 | F15: =COUNTIFS('All Seasons'!$C$2:$C$163,A15,'All Seasons'!$H$2:$H$163,"Champion")+COUNTIFS('All Seasons'!$C$2:$C$163,A15,'All Seasons'!$H$2:$H$163,"Runner-Up")+COUNTIFS('All Seasons'!$C$2:$C$163,A15,'All Seasons'!$H$2:$H$163,"3rd Place")+COUNTIFS('All Seasons'!$C$2:$C$163,A15,'All Seasons'!$H$2:$H$163,"4th Place")+COUNTIFS('All Seasons'!$C$2:$C$163,A15,'All Seasons'!$H$2:$H$163,"Made Playoffs") -> 8 | G15: =SUMIF('All Seasons'!$C$2:$C$163,A15,'All Seasons'!$E$2:$E$163) -> 101 | H15: =SUMIF('All Seasons'!$C$2:$C$163,A15,'All Seasons'!$F$2:$F$163) -> 85 | I15: =IF((G15+H15)=0,0,G15/(G15+H15)) -> 0.54301075 | J15: =SUMIF('All Seasons'!$C$2:$C$163,A15,'All Seasons'!$G$2:$G$163) -> 22505.04
A17: thowd's row highlighted for reference. Sort by Championships / Win % as you like — this is a live filterable table.

Sheet Your Career (thowd)
A1: Season | B1: Team Name | C1: Reg. Season Rank | D1: W | E1: L | F1: Points For | G1: Playoff Result
A2: 2012 | B2: =INDEX('All Seasons'!$D$2:$D$163,MATCH(1,('All Seasons'!$A$2:$A$163=A2)*('All Seasons'!$C$2:$C$163="thowd"),0)) -> I'm Diggin' This Gurley | C2: =INDEX('All Seasons'!$B$2:$B$163,MATCH(1,('All Seasons'!$A$2:$A$163=A2)*('All Seasons'!$C$2:$C$163="thowd"),0)) -> 6 | D2: =INDEX('All Seasons'!$E$2:$E$163,MATCH(1,('All Seasons'!$A$2:$A$163=A2)*('All Seasons'!$C$2:$C$163="thowd"),0)) -> 5 | E2: =INDEX('All Seasons'!$F$2:$F$163,MATCH(1,('All Seasons'!$A$2:$A$163=A2)*('All Seasons'!$C$2:$C$163="thowd"),0)) -> 7 | F2: =INDEX('All Seasons'!$G$2:$G$163,MATCH(1,('All Seasons'!$A$2:$A$163=A2)*('All Seasons'!$C$2:$C$163="thowd"),0)) -> 1405 | G2: =INDEX('All Seasons'!$H$2:$H$163,MATCH(1,('All Seasons'!$A$2:$A$163=A2)*('All Seasons'!$C$2:$C$163="thowd"),0)) -> Missed Playoffs
A3: 2013 | B3: =INDEX('All Seasons'!$D$2:$D$163,MATCH(1,('All Seasons'!$A$2:$A$163=A3)*('All Seasons'!$C$2:$C$163="thowd"),0)) -> I'm Diggin' This Gurley | C3: =INDEX('All Seasons'!$B$2:$B$163,MATCH(1,('All Seasons'!$A$2:$A$163=A3)*('All Seasons'!$C$2:$C$163="thowd"),0)) -> 3 | D3: =INDEX('All Seasons'!$E$2:$E$163,MATCH(1,('All Seasons'!$A$2:$A$163=A3)*('All Seasons'!$C$2:$C$163="thowd"),0)) -> 8 | E3: =INDEX('All Seasons'!$F$2:$F$163,MATCH(1,('All Seasons'!$A$2:$A$163=A3)*('All Seasons'!$C$2:$C$163="thowd"),0)) -> 5 | F3: =INDEX('All Seasons'!$G$2:$G$163,MATCH(1,('All Seasons'!$A$2:$A$163=A3)*('All Seasons'!$C$2:$C$163="thowd"),0)) -> 1608 | G3: =INDEX('All Seasons'!$H$2:$H$163,MATCH(1,('All Seasons'!$A$2:$A$163=A3)*('All Seasons'!$C$2:$C$163="thowd"),0)) -> 4th Place
A4: 2014 | B4: =INDEX('All Seasons'!$D$2:$D$163,MATCH(1,('All Seasons'!$A$2:$A$163=A4)*('All Seasons'!$C$2:$C$163="thowd"),0)) -> I'm Diggin' This Gurley | C4: =INDEX('All Seasons'!$B$2:$B$163,MATCH(1,('All Seasons'!$A$2:$A$163=A4)*('All Seasons'!$C$2:$C$163="thowd"),0)) -> 6 | D4: =INDEX('All Seasons'!$E$2:$E$163,MATCH(1,('All Seasons'!$A$2:$A$163=A4)*('All Seasons'!$C$2:$C$163="thowd"),0)) -> 6 | E4: =INDEX('All Seasons'!$F$2:$F$163,MATCH(1,('All Seasons'!$A$2:$A$163=A4)*('All Seasons'!$C$2:$C$163="thowd"),0)) -> 7 | F4: =INDEX('All Seasons'!$G$2:$G$163,MATCH(1,('All Seasons'!$A$2:$A$163=A4)*('All Seasons'!$C$2:$C$163="thowd"),0)) -> 1481 | G4: =INDEX('All Seasons'!$H$2:$H$163,MATCH(1,('All Seasons'!$A$2:$A$163=A4)*('All Seasons'!$C$2:$C$163="thowd"),0)) -> Missed Playoffs
A5: 2015 | B5: =INDEX('All Seasons'!$D$2:$D$163,MATCH(1,('All Seasons'!$A$2:$A$163=A5)*('All Seasons'!$C$2:$C$163="thowd"),0)) -> I'm Diggin' This Gurley | C5: =INDEX('All Seasons'!$B$2:$B$163,MATCH(1,('All Seasons'!$A$2:$A$163=A5)*('All Seasons'!$C$2:$C$163="thowd"),0)) -> 5 | D5: =INDEX('All Seasons'!$E$2:$E$163,MATCH(1,('All Seasons'!$A$2:$A$163=A5)*('All Seasons'!$C$2:$C$163="thowd"),0)) -> 8 | E5: =INDEX('All Seasons'!$F$2:$F$163,MATCH(1,('All Seasons'!$A$2:$A$163=A5)*('All Seasons'!$C$2:$C$163="thowd"),0)) -> 5 | F5: =INDEX('All Seasons'!$G$2:$G$163,MATCH(1,('All Seasons'!$A$2:$A$163=A5)*('All Seasons'!$C$2:$C$163="thowd"),0)) -> 1491 | G5: =INDEX('All Seasons'!$H$2:$H$163,MATCH(1,('All Seasons'!$A$2:$A$163=A5)*('All Seasons'!$C$2:$C$163="thowd"),0)) -> Made Playoffs
A6: 2016 | B6: =INDEX('All Seasons'!$D$2:$D$163,MATCH(1,('All Seasons'!$A$2:$A$163=A6)*('All Seasons'!$C$2:$C$163="thowd"),0)) -> I'm Diggin' This Gurley | C6: =INDEX('All Seasons'!$B$2:$B$163,MATCH(1,('All Seasons'!$A$2:$A$163=A6)*('All Seasons'!$C$2:$C$163="thowd"),0)) -> 12 | D6: =INDEX('All Seasons'!$E$2:$E$163,MATCH(1,('All Seasons'!$A$2:$A$163=A6)*('All Seasons'!$C$2:$C$163="thowd"),0)) -> 4 | E6: =INDEX('All Seasons'!$F$2:$F$163,MATCH(1,('All Seasons'!$A$2:$A$163=A6)*('All Seasons'!$C$2:$C$163="thowd"),0)) -> 9 | F6: =INDEX('All Seasons'!$G$2:$G$163,MATCH(1,('All Seasons'!$A$2:$A$163=A6)*('All Seasons'!$C$2:$C$163="thowd"),0)) -> 1590.6 | G6: =INDEX('All Seasons'!$H$2:$H$163,MATCH(1,('All Seasons'!$A$2:$A$163=A6)*('All Seasons'!$C$2:$C$163="thowd"),0)) -> Missed Playoffs
A7: 2017 | B7: =INDEX('All Seasons'!$D$2:$D$163,MATCH(1,('All Seasons'!$A$2:$A$163=A7)*('All Seasons'!$C$2:$C$163="thowd"),0)) -> I'm Diggin' This Gurley | C7: =INDEX('All Seasons'!$B$2:$B$163,MATCH(1,('All Seasons'!$A$2:$A$163=A7)*('All Seasons'!$C$2:$C$163="thowd"),0)) -> 5 | D7: =INDEX('All Seasons'!$E$2:$E$163,MATCH(1,('All Seasons'!$A$2:$A$163=A7)*('All Seasons'!$C$2:$C$163="thowd"),0)) -> 7 | E7: =INDEX('All Seasons'!$F$2:$F$163,MATCH(1,('All Seasons'!$A$2:$A$163=A7)*('All Seasons'!$C$2:$C$163="thowd"),0)) -> 6 | F7: =INDEX('All Seasons'!$G$2:$G$163,MATCH(1,('All Seasons'!$A$2:$A$163=A7)*('All Seasons'!$C$2:$C$163="thowd"),0)) -> 1549 | G7: =INDEX('All Seasons'!$H$2:$H$163,MATCH(1,('All Seasons'!$A$2:$A$163=A7)*('All Seasons'!$C$2:$C$163="thowd"),0)) -> Champion
A8: 2018 | B8: =INDEX('All Seasons'!$D$2:$D$163,MATCH(1,('All Seasons'!$A$2:$A$163=A8)*('All Seasons'!$C$2:$C$163="thowd"),0)) -> I'm Diggin' This Gurley | C8: =INDEX('All Seasons'!$B$2:$B$163,MATCH(1,('All Seasons'!$A$2:$A$163=A8)*('All Seasons'!$C$2:$C$163="thowd"),0)) -> 2 | D8: =INDEX('All Seasons'!$E$2:$E$163,MATCH(1,('All Seasons'!$A$2:$A$163=A8)*('All Seasons'!$C$2:$C$163="thowd"),0)) -> 9 | E8: =INDEX('All Seasons'!$F$2:$F$163,MATCH(1,('All Seasons'!$A$2:$A$163=A8)*('All Seasons'!$C$2:$C$163="thowd"),0)) -> 4 | F8: =INDEX('All Seasons'!$G$2:$G$163,MATCH(1,('All Seasons'!$A$2:$A$163=A8)*('All Seasons'!$C$2:$C$163="thowd"),0)) -> 1677.1 | G8: =INDEX('All Seasons'!$H$2:$H$163,MATCH(1,('All Seasons'!$A$2:$A$163=A8)*('All Seasons'!$C$2:$C$163="thowd"),0)) -> 4th Place
A9: 2019 | B9: =INDEX('All Seasons'!$D$2:$D$163,MATCH(1,('All Seasons'!$A$2:$A$163=A9)*('All Seasons'!$C$2:$C$163="thowd"),0)) -> CAM JUju DIGGs IT!?!? | C9: =INDEX('All Seasons'!$B$2:$B$163,MATCH(1,('All Seasons'!$A$2:$A$163=A9)*('All Seasons'!$C$2:$C$163="thowd"),0)) -> 5 | D9: =INDEX('All Seasons'!$E$2:$E$163,MATCH(1,('All Seasons'!$A$2:$A$163=A9)*('All Seasons'!$C$2:$C$163="thowd"),0)) -> 8 | E9: =INDEX('All Seasons'!$F$2:$F$163,MATCH(1,('All Seasons'!$A$2:$A$163=A9)*('All Seasons'!$C$2:$C$163="thowd"),0)) -> 5 | F9: =INDEX('All Seasons'!$G$2:$G$163,MATCH(1,('All Seasons'!$A$2:$A$163=A9)*('All Seasons'!$C$2:$C$163="thowd"),0)) -> 1564.94 | G9: =INDEX('All Seasons'!$H$2:$H$163,MATCH(1,('All Seasons'!$A$2:$A$163=A9)*('All Seasons'!$C$2:$C$163="thowd"),0)) -> Champion
A10: 2020 | B10: =INDEX('All Seasons'!$D$2:$D$163,MATCH(1,('All Seasons'!$A$2:$A$163=A10)*('All Seasons'!$C$2:$C$163="thowd"),0)) -> #Champions | C10: =INDEX('All Seasons'!$B$2:$B$163,MATCH(1,('All Seasons'!$A$2:$A$163=A10)*('All Seasons'!$C$2:$C$163="thowd"),0)) -> 7 | D10: =INDEX('All Seasons'!$E$2:$E$163,MATCH(1,('All Seasons'!$A$2:$A$163=A10)*('All Seasons'!$C$2:$C$163="thowd"),0)) -> 6 | E10: =INDEX('All Seasons'!$F$2:$F$163,MATCH(1,('All Seasons'!$A$2:$A$163=A10)*('All Seasons'!$C$2:$C$163="thowd"),0)) -> 7 | F10: =INDEX('All Seasons'!$G$2:$G$163,MATCH(1,('All Seasons'!$A$2:$A$163=A10)*('All Seasons'!$C$2:$C$163="thowd"),0)) -> 1563.24 | G10: =INDEX('All Seasons'!$H$2:$H$163,MATCH(1,('All Seasons'!$A$2:$A$163=A10)*('All Seasons'!$C$2:$C$163="thowd"),0)) -> Missed Playoffs
A11: 2021 | B11: =INDEX('All Seasons'!$D$2:$D$163,MATCH(1,('All Seasons'!$A$2:$A$163=A11)*('All Seasons'!$C$2:$C$163="thowd"),0)) -> Hasta Laviska | C11: =INDEX('All Seasons'!$B$2:$B$163,MATCH(1,('All Seasons'!$A$2:$A$163=A11)*('All Seasons'!$C$2:$C$163="thowd"),0)) -> 7 | D11: =INDEX('All Seasons'!$E$2:$E$163,MATCH(1,('All Seasons'!$A$2:$A$163=A11)*('All Seasons'!$C$2:$C$163="thowd"),0)) -> 7 | E11: =INDEX('All Seasons'!$F$2:$F$163,MATCH(1,('All Seasons'!$A$2:$A$163=A11)*('All Seasons'!$C$2:$C$163="thowd"),0)) -> 7 | F11: =INDEX('All Seasons'!$G$2:$G$163,MATCH(1,('All Seasons'!$A$2:$A$163=A11)*('All Seasons'!$C$2:$C$163="thowd"),0)) -> 1822.16 | G11: =INDEX('All Seasons'!$H$2:$H$163,MATCH(1,('All Seasons'!$A$2:$A$163=A11)*('All Seasons'!$C$2:$C$163="thowd"),0)) -> Missed Playoffs
A12: 2022 | B12: =INDEX('All Seasons'!$D$2:$D$163,MATCH(1,('All Seasons'!$A$2:$A$163=A12)*('All Seasons'!$C$2:$C$163="thowd"),0)) -> Dark side, Strong side | C12: =INDEX('All Seasons'!$B$2:$B$163,MATCH(1,('All Seasons'!$A$2:$A$163=A12)*('All Seasons'!$C$2:$C$163="thowd"),0)) -> 8 | D12: =INDEX('All Seasons'!$E$2:$E$163,MATCH(1,('All Seasons'!$A$2:$A$163=A12)*('All Seasons'!$C$2:$C$163="thowd"),0)) -> 5 | E12: =INDEX('All Seasons'!$F$2:$F$163,MATCH(1,('All Seasons'!$A$2:$A$163=A12)*('All Seasons'!$C$2:$C$163="thowd"),0)) -> 9 | F12: =INDEX('All Seasons'!$G$2:$G$163,MATCH(1,('All Seasons'!$A$2:$A$163=A12)*('All Seasons'!$C$2:$C$163="thowd"),0)) -> 1629.36 | G12: =INDEX('All Seasons'!$H$2:$H$163,MATCH(1,('All Seasons'!$A$2:$A$163=A12)*('All Seasons'!$C$2:$C$163="thowd"),0)) -> Missed Playoffs
A13: 2023 | B13: =INDEX('All Seasons'!$D$2:$D$163,MATCH(1,('All Seasons'!$A$2:$A$163=A13)*('All Seasons'!$C$2:$C$163="thowd"),0)) -> The Kelce Era | C13: =INDEX('All Seasons'!$B$2:$B$163,MATCH(1,('All Seasons'!$A$2:$A$163=A13)*('All Seasons'!$C$2:$C$163="thowd"),0)) -> 2 | D13: =INDEX('All Seasons'!$E$2:$E$163,MATCH(1,('All Seasons'!$A$2:$A$163=A13)*('All Seasons'!$C$2:$C$163="thowd"),0)) -> 10 | E13: =INDEX('All Seasons'!$F$2:$F$163,MATCH(1,('All Seasons'!$A$2:$A$163=A13)*('All Seasons'!$C$2:$C$163="thowd"),0)) -> 4 | F13: =INDEX('All Seasons'!$G$2:$G$163,MATCH(1,('All Seasons'!$A$2:$A$163=A13)*('All Seasons'!$C$2:$C$163="thowd"),0)) -> 1807.9 | G13: =INDEX('All Seasons'!$H$2:$H$163,MATCH(1,('All Seasons'!$A$2:$A$163=A13)*('All Seasons'!$C$2:$C$163="thowd"),0)) -> 3rd Place
... A15: 2025 | B15: =INDEX('All Seasons'!$D$2:$D$163,MATCH(1,('All Seasons'!$A$2:$A$163=A15)*('All Seasons'!$C$2:$C$163="thowd"),0)) -> Run CM-Sun God | C15: =INDEX('All Seasons'!$B$2:$B$163,MATCH(1,('All Seasons'!$A$2:$A$163=A15)*('All Seasons'!$C$2:$C$163="thowd"),0)) -> 2 | D15: =INDEX('All Seasons'!$E$2:$E$163,MATCH(1,('All Seasons'!$A$2:$A$163=A15)*('All Seasons'!$C$2:$C$163="thowd"),0)) -> 9 | E15: =INDEX('All Seasons'!$F$2:$F$163,MATCH(1,('All Seasons'!$A$2:$A$163=A15)*('All Seasons'!$C$2:$C$163="thowd"),0)) -> 5 | F15: =INDEX('All Seasons'!$G$2:$G$163,MATCH(1,('All Seasons'!$A$2:$A$163=A15)*('All Seasons'!$C$2:$C$163="thowd"),0)) -> 1693.4 | G15: =INDEX('All Seasons'!$H$2:$H$163,MATCH(1,('All Seasons'!$A$2:$A$163=A15)*('All Seasons'!$C$2:$C$163="thowd"),0)) -> Champion
A16: CAREER | D16: =SUM(D2:D15) -> 101 | E16: =SUM(E2:E15) -> 85 | F16: =SUM(F2:F15) -> 22505.04
A17: Career Win % | D17: =D16/(D16+E16) -> 0.54301075

Sheet League Awards
A2: LEAGUE AWARDS
A3: Luck rating, point differential, and career superlatives — modeled on the stat categories dedicated league-history tools (e.g. Fantasy Record Book) track.
A5: TROPHY CASE
A6: Manager | B6: Seasons | C6: Titles | D6: Runner-Ups | E6: Sackos | F6: Career PF | G6: Career PA | H6: Point Diff | I6: Avg Luck Rating
A7: GBClark | B7: =COUNTIF('All Seasons'!$C$2:$C$163,A7) -> 14 | C7: =COUNTIFS('All Seasons'!$C$2:$C$163,A7,'All Seasons'!$H$2:$H$163,"Champion") -> 0 | D7: =COUNTIFS('All Seasons'!$C$2:$C$163,A7,'All Seasons'!$H$2:$H$163,"Runner-Up") -> 0 | E7: =SUMIFS('All Seasons'!$M$2:$M$163,'All Seasons'!$C$2:$C$163,A7) -> 2 | F7: =SUMIF('All Seasons'!$C$2:$C$163,A7,'All Seasons'!$G$2:$G$163) -> 20930 | G7: =SUMIF('All Seasons'!$C$2:$C$163,A7,'All Seasons'!$I$2:$I$163) -> 21818.78 | H7: =F7-G7 -> -888.78 | I7: =AVERAGEIF('All Seasons'!$C$2:$C$163,A7,'All Seasons'!$L$2:$L$163) -> 0.0014259647
A8: JPeters19 | B8: =COUNTIF('All Seasons'!$C$2:$C$163,A8) -> 12 | C8: =COUNTIFS('All Seasons'!$C$2:$C$163,A8,'All Seasons'!$H$2:$H$163,"Champion") -> 1 | D8: =COUNTIFS('All Seasons'!$C$2:$C$163,A8,'All Seasons'!$H$2:$H$163,"Runner-Up") -> 2 | E8: =SUMIFS('All Seasons'!$M$2:$M$163,'All Seasons'!$C$2:$C$163,A8) -> 1 | F8: =SUMIF('All Seasons'!$C$2:$C$163,A8,'All Seasons'!$G$2:$G$163) -> 18638.88 | G8: =SUMIF('All Seasons'!$C$2:$C$163,A8,'All Seasons'!$I$2:$I$163) -> 19282 | H8: =F8-G8 -> -643.12 | I8: =AVERAGEIF('All Seasons'!$C$2:$C$163,A8,'All Seasons'!$L$2:$L$163) -> -0.021311749
A9: Keughes | B9: =COUNTIF('All Seasons'!$C$2:$C$163,A9) -> 2 | C9: =COUNTIFS('All Seasons'!$C$2:$C$163,A9,'All Seasons'!$H$2:$H$163,"Champion") -> 0 | D9: =COUNTIFS('All Seasons'!$C$2:$C$163,A9,'All Seasons'!$H$2:$H$163,"Runner-Up") -> 0 | E9: =SUMIFS('All Seasons'!$M$2:$M$163,'All Seasons'!$C$2:$C$163,A9) -> 1 | F9: =SUMIF('All Seasons'!$C$2:$C$163,A9,'All Seasons'!$G$2:$G$163) -> 2943.28 | G9: =SUMIF('All Seasons'!$C$2:$C$163,A9,'All Seasons'!$I$2:$I$163) -> 3160.3 | H9: =F9-G9 -> -217.02 | I9: =AVERAGEIF('All Seasons'!$C$2:$C$163,A9,'All Seasons'!$L$2:$L$163) -> -0.02706197
A10: SeanOMara | B10: =COUNTIF('All Seasons'!$C$2:$C$163,A10) -> 11 | C10: =COUNTIFS('All Seasons'!$C$2:$C$163,A10,'All Seasons'!$H$2:$H$163,"Champion") -> 0 | D10: =COUNTIFS('All Seasons'!$C$2:$C$163,A10,'All Seasons'!$H$2:$H$163,"Runner-Up") -> 1 | E10: =SUMIFS('All Seasons'!$M$2:$M$163,'All Seasons'!$C$2:$C$163,A10) -> 0 | F10: =SUMIF('All Seasons'!$C$2:$C$163,A10,'All Seasons'!$G$2:$G$163) -> 16905.2 | G10: =SUMIF('All Seasons'!$C$2:$C$163,A10,'All Seasons'!$I$2:$I$163) -> 17316.2 | H10: =F10-G10 -> -411 | I10: =AVERAGEIF('All Seasons'!$C$2:$C$163,A10,'All Seasons'!$L$2:$L$163) -> -0.014342375
A11: TylerKeel | B11: =COUNTIF('All Seasons'!$C$2:$C$163,A11) -> 14 | C11: =COUNTIFS('All Seasons'!$C$2:$C$163,A11,'All Seasons'!$H$2:$H$163,"Champion") -> 0 | D11: =COUNTIFS('All Seasons'!$C$2:$C$163,A11,'All Seasons'!$H$2:$H$163,"Runner-Up") -> 1 | E11: =SUMIFS('All Seasons'!$M$2:$M$163,'All Seasons'!$C$2:$C$163,A11) -> 3 | F11: =SUMIF('All Seasons'!$C$2:$C$163,A11,'All Seasons'!$G$2:$G$163) -> 20895.54 | G11: =SUMIF('All Seasons'!$C$2:$C$163,A11,'All Seasons'!$I$2:$I$163) -> 21957.82 | H11: =F11-G11 -> -1062.28 | I11: =AVERAGEIF('All Seasons'!$C$2:$C$163,A11,'All Seasons'!$L$2:$L$163) -> -0.089170649
A12: YungSimba | B12: =COUNTIF('All Seasons'!$C$2:$C$163,A12) -> 14 | C12: =COUNTIFS('All Seasons'!$C$2:$C$163,A12,'All Seasons'!$H$2:$H$163,"Champion") -> 0 | D12: =COUNTIFS('All Seasons'!$C$2:$C$163,A12,'All Seasons'!$H$2:$H$163,"Runner-Up") -> 1 | E12: =SUMIFS('All Seasons'!$M$2:$M$163,'All Seasons'!$C$2:$C$163,A12) -> 0 | F12: =SUMIF('All Seasons'!$C$2:$C$163,A12,'All Seasons'!$G$2:$G$163) -> 21533.64 | G12: =SUMIF('All Seasons'!$C$2:$C$163,A12,'All Seasons'!$I$2:$I$163) -> 21412.12 | H12: =F12-G12 -> 121.52 | I12: =AVERAGEIF('All Seasons'!$C$2:$C$163,A12,'All Seasons'!$L$2:$L$163) -> 0.024010081
A13: amenr5 | B13: =COUNTIF('All Seasons'!$C$2:$C$163,A13) -> 3 | C13: =COUNTIFS('All Seasons'!$C$2:$C$163,A13,'All Seasons'!$H$2:$H$163,"Champion") -> 0 | D13: =COUNTIFS('All Seasons'!$C$2:$C$163,A13,'All Seasons'!$H$2:$H$163,"Runner-Up") -> 0 | E13: =SUMIFS('All Seasons'!$M$2:$M$163,'All Seasons'!$C$2:$C$163,A13) -> 0 | F13: =SUMIF('All Seasons'!$C$2:$C$163,A13,'All Seasons'!$G$2:$G$163) -> 4623.98 | G13: =SUMIF('All Seasons'!$C$2:$C$163,A13,'All Seasons'!$I$2:$I$163) -> 4788.96 | H13: =F13-G13 -> -164.98 | I13: =AVERAGEIF('All Seasons'!$C$2:$C$163,A13,'All Seasons'!$L$2:$L$163) -> -0.07433734
A14: assif | B14: =COUNTIF('All Seasons'!$C$2:$C$163,A14) -> 11 | C14: =COUNTIFS('All Seasons'!$C$2:$C$163,A14,'All Seasons'!$H$2:$H$163,"Champion") -> 0 | D14: =COUNTIFS('All Seasons'!$C$2:$C$163,A14,'All Seasons'!$H$2:$H$163,"Runner-Up") -> 0 | E14: =SUMIFS('All Seasons'!$M$2:$M$163,'All Seasons'!$C$2:$C$163,A14) -> 2 | F14: =SUMIF('All Seasons'!$C$2:$C$163,A14,'All Seasons'!$G$2:$G$163) -> 16309.9 | G14: =SUMIF('All Seasons'!$C$2:$C$163,A14,'All Seasons'!$I$2:$I$163) -> 17257.86 | H14: =F14-G14 -> -947.96 | I14: =AVERAGEIF('All Seasons'!$C$2:$C$163,A14,'All Seasons'!$L$2:$L$163) -> -0.056517387
A15: bcorrigan30 | B15: =COUNTIF('All Seasons'!$C$2:$C$163,A15) -> 14 | C15: =COUNTIFS('All Seasons'!$C$2:$C$163,A15,'All Seasons'!$H$2:$H$163,"Champion") -> 0 | D15: =COUNTIFS('All Seasons'!$C$2:$C$163,A15,'All Seasons'!$H$2:$H$163,"Runner-Up") -> 1 | E15: =SUMIFS('All Seasons'!$M$2:$M$163,'All Seasons'!$C$2:$C$163,A15) -> 1 | F15: =SUMIF('All Seasons'!$C$2:$C$163,A15,'All Seasons'!$G$2:$G$163) -> 22158.1 | G15: =SUMIF('All Seasons'!$C$2:$C$163,A15,'All Seasons'!$I$2:$I$163) -> 21122.98 | H15: =F15-G15 -> 1035.12 | I15: =AVERAGEIF('All Seasons'!$C$2:$C$163,A15,'All Seasons'!$L$2:$L$163) -> 0.024630267
A16: dnevels8 | B16: =COUNTIF('All Seasons'!$C$2:$C$163,A16) -> 11 | C16: =COUNTIFS('All Seasons'!$C$2:$C$163,A16,'All Seasons'!$H$2:$H$163,"Champion") -> 1 | D16: =COUNTIFS('All Seasons'!$C$2:$C$163,A16,'All Seasons'!$H$2:$H$163,"Runner-Up") -> 0 | E16: =SUMIFS('All Seasons'!$M$2:$M$163,'All Seasons'!$C$2:$C$163,A16) -> 1 | F16: =SUMIF('All Seasons'!$C$2:$C$163,A16,'All Seasons'!$G$2:$G$163) -> 16876.88 | G16: =SUMIF('All Seasons'!$C$2:$C$163,A16,'All Seasons'!$I$2:$I$163) -> 17524.96 | H16: =F16-G16 -> -648.08 | I16: =AVERAGEIF('All Seasons'!$C$2:$C$163,A16,'All Seasons'!$L$2:$L$163) -> -0.022367613
A17: jphn744 | B17: =COUNTIF('All Seasons'!$C$2:$C$163,A17) -> 14 | C17: =COUNTIFS('All Seasons'!$C$2:$C$163,A17,'All Seasons'!$H$2:$H$163,"Champion") -> 5 | D17: =COUNTIFS('All Seasons'!$C$2:$C$163,A17,'All Seasons'!$H$2:$H$163,"Runner-Up") -> 2 | E17: =SUMIFS('All Seasons'!$M$2:$M$163,'All Seasons'!$C$2:$C$163,A17) -> 0 | F17: =SUMIF('All Seasons'!$C$2:$C$163,A17,'All Seasons'!$G$2:$G$163) -> 22898.4 | G17: =SUMIF('All Seasons'!$C$2:$C$163,A17,'All Seasons'!$I$2:$I$163) -> 21900.2 | H17: =F17-G17 -> 998.2 | I17: =AVERAGEIF('All Seasons'!$C$2:$C$163,A17,'All Seasons'!$L$2:$L$163) -> 0.022108733
A18: kdavis | B18: =COUNTIF('All Seasons'!$C$2:$C$163,A18) -> 14 | C18: =COUNTIFS('All Seasons'!$C$2:$C$163,A18,'All Seasons'!$H$2:$H$163,"Champion") -> 2 | D18: =COUNTIFS('All Seasons'!$C$2:$C$163,A18,'All Seasons'!$H$2:$H$163,"Runner-Up") -> 2 | E18: =SUMIFS('All Seasons'!$M$2:$M$163,'All Seasons'!$C$2:$C$163,A18) -> 0 | F18: =SUMIF('All Seasons'!$C$2:$C$163,A18,'All Seasons'!$G$2:$G$163) -> 23226.92 | G18: =SUMIF('All Seasons'!$C$2:$C$163,A18,'All Seasons'!$I$2:$I$163) -> 21820.38 | H18: =F18-G18 -> 1406.54 | I18: =AVERAGEIF('All Seasons'!$C$2:$C$163,A18,'All Seasons'!$L$2:$L$163) -> 0.087902171
... A20: thowd | B20: =COUNTIF('All Seasons'!$C$2:$C$163,A20) -> 14 | C20: =COUNTIFS('All Seasons'!$C$2:$C$163,A20,'All Seasons'!$H$2:$H$163,"Champion") -> 3 | D20: =COUNTIFS('All Seasons'!$C$2:$C$163,A20,'All Seasons'!$H$2:$H$163,"Runner-Up") -> 1 | E20: =SUMIFS('All Seasons'!$M$2:$M$163,'All Seasons'!$C$2:$C$163,A20) -> 1 | F20: =SUMIF('All Seasons'!$C$2:$C$163,A20,'All Seasons'!$G$2:$G$163) -> 22505.04 | G20: =SUMIF('All Seasons'!$C$2:$C$163,A20,'All Seasons'!$I$2:$I$163) -> 21398.1 | H20: =F20-G20 -> 1106.94 | I20: =AVERAGEIF('All Seasons'!$C$2:$C$163,A20,'All Seasons'!$L$2:$L$163) -> 0.011661918
A21: Sacko = worst regular-season finish that year (proxy for last place; not a separately tracked award in either source).
A22: Luck Rating = actual win% minus Pythagorean-expected win% (based on points scored vs. allowed, exponent 2.37). Positive = overperformed points; negative = underperformed.
A25: SEASON SUPERLATIVES
A26: Season | B26: Champion | C26: Highest Scorer | D26: Best Record | E26: Luckiest Team | F26: Unluckiest Team
A27: 2012 | B27: =INDEX('All Seasons'!$C$2:$C$163,MATCH(1,('All Seasons'!$A$2:$A$163=A27)*('All Seasons'!$H$2:$H$163="Champion"),0)) -> JPeters19 | C27: =INDEX('All Seasons'!$C$2:$C$163,MATCH(1,('All Seasons'!$A$2:$A$163=A27)*('All Seasons'!$G$2:$G$163=_xlfn.MAXIFS('All Seasons'!$G$2:$G$163,'All Seasons'!$A$2:$A$163,A27)),0)) -> GBClark | D27: =INDEX('All Seasons'!$C$2:$C$163,MATCH(1,('All Seasons'!$A$2:$A$163=A27)*('All Seasons'!$B$2:$B$163=1),0)) -> peterbrune | E27: =INDEX('All Seasons'!$C$2:$C$163,MATCH(1,('All Seasons'!$A$2:$A$163=A27)*('All Seasons'!$L$2:$L$163=_xlfn.MAXIFS('All Seasons'!$L$2:$L$163,'All Seasons'!$A$2:$A$163,A27)),0)) -> peterbrune | F27: =INDEX('All Seasons'!$C$2:$C$163,MATCH(1,('All Seasons'!$A$2:$A$163=A27)*('All Seasons'!$L$2:$L$163=_xlfn.MINIFS('All Seasons'!$L$2:$L$163,'All Seasons'!$A$2:$A$163,A27)),0)) -> bcorrigan30
A28: 2013 | B28: =INDEX('All Seasons'!$C$2:$C$163,MATCH(1,('All Seasons'!$A$2:$A$163=A28)*('All Seasons'!$H$2:$H$163="Champion"),0)) -> jphn744 | C28: =INDEX('All Seasons'!$C$2:$C$163,MATCH(1,('All Seasons'!$A$2:$A$163=A28)*('All Seasons'!$G$2:$G$163=_xlfn.MAXIFS('All Seasons'!$G$2:$G$163,'All Seasons'!$A$2:$A$163,A28)),0)) -> jphn744 | D28: =INDEX('All Seasons'!$C$2:$C$163,MATCH(1,('All Seasons'!$A$2:$A$163=A28)*('All Seasons'!$B$2:$B$163=1),0)) -> YungSimba | E28: =INDEX('All Seasons'!$C$2:$C$163,MATCH(1,('All Seasons'!$A$2:$A$163=A28)*('All Seasons'!$L$2:$L$163=_xlfn.MAXIFS('All Seasons'!$L$2:$L$163,'All Seasons'!$A$2:$A$163,A28)),0)) -> YungSimba | F28: =INDEX('All Seasons'!$C$2:$C$163,MATCH(1,('All Seasons'!$A$2:$A$163=A28)*('All Seasons'!$L$2:$L$163=_xlfn.MINIFS('All Seasons'!$L$2:$L$163,'All Seasons'!$A$2:$A$163,A28)),0)) -> TylerKeel
A29: 2014 | B29: =INDEX('All Seasons'!$C$2:$C$163,MATCH(1,('All Seasons'!$A$2:$A$163=A29)*('All Seasons'!$H$2:$H$163="Champion"),0)) -> jphn744 | C29: =INDEX('All Seasons'!$C$2:$C$163,MATCH(1,('All Seasons'!$A$2:$A$163=A29)*('All Seasons'!$G$2:$G$163=_xlfn.MAXIFS('All Seasons'!$G$2:$G$163,'All Seasons'!$A$2:$A$163,A29)),0)) -> kdavis | D29: =INDEX('All Seasons'!$C$2:$C$163,MATCH(1,('All Seasons'!$A$2:$A$163=A29)*('All Seasons'!$B$2:$B$163=1),0)) -> kdavis | E29: =INDEX('All Seasons'!$C$2:$C$163,MATCH(1,('All Seasons'!$A$2:$A$163=A29)*('All Seasons'!$L$2:$L$163=_xlfn.MAXIFS('All Seasons'!$L$2:$L$163,'All Seasons'!$A$2:$A$163,A29)),0)) -> kdavis | F29: =INDEX('All Seasons'!$C$2:$C$163,MATCH(1,('All Seasons'!$A$2:$A$163=A29)*('All Seasons'!$L$2:$L$163=_xlfn.MINIFS('All Seasons'!$L$2:$L$163,'All Seasons'!$A$2:$A$163,A29)),0)) -> TylerKeel
A30: 2015 | B30: =INDEX('All Seasons'!$C$2:$C$163,MATCH(1,('All Seasons'!$A$2:$A$163=A30)*('All Seasons'!$H$2:$H$163="Champion"),0)) -> peterbrune | C30: =INDEX('All Seasons'!$C$2:$C$163,MATCH(1,('All Seasons'!$A$2:$A$163=A30)*('All Seasons'!$G$2:$G$163=_xlfn.MAXIFS('All Seasons'!$G$2:$G$163,'All Seasons'!$A$2:$A$163,A30)),0)) -> kdavis | D30: =INDEX('All Seasons'!$C$2:$C$163,MATCH(1,('All Seasons'!$A$2:$A$163=A30)*('All Seasons'!$B$2:$B$163=1),0)) -> YungSimba | E30: =INDEX('All Seasons'!$C$2:$C$163,MATCH(1,('All Seasons'!$A$2:$A$163=A30)*('All Seasons'!$L$2:$L$163=_xlfn.MAXIFS('All Seasons'!$L$2:$L$163,'All Seasons'!$A$2:$A$163,A30)),0)) -> SeanOMara | F30: =INDEX('All Seasons'!$C$2:$C$163,MATCH(1,('All Seasons'!$A$2:$A$163=A30)*('All Seasons'!$L$2:$L$163=_xlfn.MINIFS('All Seasons'!$L$2:$L$163,'All Seasons'!$A$2:$A$163,A30)),0)) -> assif
A31: 2016 | B31: =INDEX('All Seasons'!$C$2:$C$163,MATCH(1,('All Seasons'!$A$2:$A$163=A31)*('All Seasons'!$H$2:$H$163="Champion"),0)) -> peterbrune | C31: =INDEX('All Seasons'!$C$2:$C$163,MATCH(1,('All Seasons'!$A$2:$A$163=A31)*('All Seasons'!$G$2:$G$163=_xlfn.MAXIFS('All Seasons'!$G$2:$G$163,'All Seasons'!$A$2:$A$163,A31)),0)) -> assif | D31: =INDEX('All Seasons'!$C$2:$C$163,MATCH(1,('All Seasons'!$A$2:$A$163=A31)*('All Seasons'!$B$2:$B$163=1),0)) -> assif | E31: =INDEX('All Seasons'!$C$2:$C$163,MATCH(1,('All Seasons'!$A$2:$A$163=A31)*('All Seasons'!$L$2:$L$163=_xlfn.MAXIFS('All Seasons'!$L$2:$L$163,'All Seasons'!$A$2:$A$163,A31)),0)) -> assif | F31: =INDEX('All Seasons'!$C$2:$C$163,MATCH(1,('All Seasons'!$A$2:$A$163=A31)*('All Seasons'!$L$2:$L$163=_xlfn.MINIFS('All Seasons'!$L$2:$L$163,'All Seasons'!$A$2:$A$163,A31)),0)) -> thowd
A32: 2017 | B32: =INDEX('All Seasons'!$C$2:$C$163,MATCH(1,('All Seasons'!$A$2:$A$163=A32)*('All Seasons'!$H$2:$H$163="Champion"),0)) -> thowd | C32: =INDEX('All Seasons'!$C$2:$C$163,MATCH(1,('All Seasons'!$A$2:$A$163=A32)*('All Seasons'!$G$2:$G$163=_xlfn.MAXIFS('All Seasons'!$G$2:$G$163,'All Seasons'!$A$2:$A$163,A32)),0)) -> jphn744 | D32: =INDEX('All Seasons'!$C$2:$C$163,MATCH(1,('All Seasons'!$A$2:$A$163=A32)*('All Seasons'!$B$2:$B$163=1),0)) -> kdavis | E32: =INDEX('All Seasons'!$C$2:$C$163,MATCH(1,('All Seasons'!$A$2:$A$163=A32)*('All Seasons'!$L$2:$L$163=_xlfn.MAXIFS('All Seasons'!$L$2:$L$163,'All Seasons'!$A$2:$A$163,A32)),0)) -> kdavis | F32: =INDEX('All Seasons'!$C$2:$C$163,MATCH(1,('All Seasons'!$A$2:$A$163=A32)*('All Seasons'!$L$2:$L$163=_xlfn.MINIFS('All Seasons'!$L$2:$L$163,'All Seasons'!$A$2:$A$163,A32)),0)) -> GBClark
A33: 2018 | B33: =INDEX('All Seasons'!$C$2:$C$163,MATCH(1,('All Seasons'!$A$2:$A$163=A33)*('All Seasons'!$H$2:$H$163="Champion"),0)) -> kdavis | C33: =INDEX('All Seasons'!$C$2:$C$163,MATCH(1,('All Seasons'!$A$2:$A$163=A33)*('All Seasons'!$G$2:$G$163=_xlfn.MAXIFS('All Seasons'!$G$2:$G$163,'All Seasons'!$A$2:$A$163,A33)),0)) -> kdavis | D33: =INDEX('All Seasons'!$C$2:$C$163,MATCH(1,('All Seasons'!$A$2:$A$163=A33)*('All Seasons'!$B$2:$B$163=1),0)) -> kdavis | E33: =INDEX('All Seasons'!$C$2:$C$163,MATCH(1,('All Seasons'!$A$2:$A$163=A33)*('All Seasons'!$L$2:$L$163=_xlfn.MAXIFS('All Seasons'!$L$2:$L$163,'All Seasons'!$A$2:$A$163,A33)),0)) -> kdavis | F33: =INDEX('All Seasons'!$C$2:$C$163,MATCH(1,('All Seasons'!$A$2:$A$163=A33)*('All Seasons'!$L$2:$L$163=_xlfn.MINIFS('All Seasons'!$L$2:$L$163,'All Seasons'!$A$2:$A$163,A33)),0)) -> TylerKeel
A34: 2019 | B34: =INDEX('All Seasons'!$C$2:$C$163,MATCH(1,('All Seasons'!$A$2:$A$163=A34)*('All Seasons'!$H$2:$H$163="Champion"),0)) -> thowd | C34: =INDEX('All Seasons'!$C$2:$C$163,MATCH(1,('All Seasons'!$A$2:$A$163=A34)*('All Seasons'!$G$2:$G$163=_xlfn.MAXIFS('All Seasons'!$G$2:$G$163,'All Seasons'!$A$2:$A$163,A34)),0)) -> kdavis | D34: =INDEX('All Seasons'!$C$2:$C$163,MATCH(1,('All Seasons'!$A$2:$A$163=A34)*('All Seasons'!$B$2:$B$163=1),0)) -> JPeters19 | E34: =INDEX('All Seasons'!$C$2:$C$163,MATCH(1,('All Seasons'!$A$2:$A$163=A34)*('All Seasons'!$L$2:$L$163=_xlfn.MAXIFS('All Seasons'!$L$2:$L$163,'All Seasons'!$A$2:$A$163,A34)),0)) -> bcorrigan30 | F34: =INDEX('All Seasons'!$C$2:$C$163,MATCH(1,('All Seasons'!$A$2:$A$163=A34)*('All Seasons'!$L$2:$L$163=_xlfn.MINIFS('All Seasons'!$L$2:$L$163,'All Seasons'!$A$2:$A$163,A34)),0)) -> assif
A35: 2020 | B35: =INDEX('All Seasons'!$C$2:$C$163,MATCH(1,('All Seasons'!$A$2:$A$163=A35)*('All Seasons'!$H$2:$H$163="Champion"),0)) -> dnevels8 | C35: =INDEX('All Seasons'!$C$2:$C$163,MATCH(1,('All Seasons'!$A$2:$A$163=A35)*('All Seasons'!$G$2:$G$163=_xlfn.MAXIFS('All Seasons'!$G$2:$G$163,'All Seasons'!$A$2:$A$163,A35)),0)) -> kdavis | D35: =INDEX('All Seasons'!$C$2:$C$163,MATCH(1,('All Seasons'!$A$2:$A$163=A35)*('All Seasons'!$B$2:$B$163=1),0)) -> kdavis | E35: =INDEX('All Seasons'!$C$2:$C$163,MATCH(1,('All Seasons'!$A$2:$A$163=A35)*('All Seasons'!$L$2:$L$163=_xlfn.MAXIFS('All Seasons'!$L$2:$L$163,'All Seasons'!$A$2:$A$163,A35)),0)) -> kdavis | F35: =INDEX('All Seasons'!$C$2:$C$163,MATCH(1,('All Seasons'!$A$2:$A$163=A35)*('All Seasons'!$L$2:$L$163=_xlfn.MINIFS('All Seasons'!$L$2:$L$163,'All Seasons'!$A$2:$A$163,A35)),0)) -> TylerKeel
A36: 2021 | B36: =INDEX('All Seasons'!$C$2:$C$163,MATCH(1,('All Seasons'!$A$2:$A$163=A36)*('All Seasons'!$H$2:$H$163="Champion"),0)) -> jphn744 | C36: =INDEX('All Seasons'!$C$2:$C$163,MATCH(1,('All Seasons'!$A$2:$A$163=A36)*('All Seasons'!$G$2:$G$163=_xlfn.MAXIFS('All Seasons'!$G$2:$G$163,'All Seasons'!$A$2:$A$163,A36)),0)) -> peterbrune | D36: =INDEX('All Seasons'!$C$2:$C$163,MATCH(1,('All Seasons'!$A$2:$A$163=A36)*('All Seasons'!$B$2:$B$163=1),0)) -> jphn744 | E36: =INDEX('All Seasons'!$C$2:$C$163,MATCH(1,('All Seasons'!$A$2:$A$163=A36)*('All Seasons'!$L$2:$L$163=_xlfn.MAXIFS('All Seasons'!$L$2:$L$163,'All Seasons'!$A$2:$A$163,A36)),0)) -> jphn744 | F36: =INDEX('All Seasons'!$C$2:$C$163,MATCH(1,('All Seasons'!$A$2:$A$163=A36)*('All Seasons'!$L$2:$L$163=_xlfn.MINIFS('All Seasons'!$L$2:$L$163,'All Seasons'!$A$2:$A$163,A36)),0)) -> GBClark
A37: 2022 | B37: =INDEX('All Seasons'!$C$2:$C$163,MATCH(1,('All Seasons'!$A$2:$A$163=A37)*('All Seasons'!$H$2:$H$163="Champion"),0)) -> kdavis | C37: =INDEX('All Seasons'!$C$2:$C$163,MATCH(1,('All Seasons'!$A$2:$A$163=A37)*('All Seasons'!$G$2:$G$163=_xlfn.MAXIFS('All Seasons'!$G$2:$G$163,'All Seasons'!$A$2:$A$163,A37)),0)) -> peterbrune | D37: =INDEX('All Seasons'!$C$2:$C$163,MATCH(1,('All Seasons'!$A$2:$A$163=A37)*('All Seasons'!$B$2:$B$163=1),0)) -> peterbrune | E37: =INDEX('All Seasons'!$C$2:$C$163,MATCH(1,('All Seasons'!$A$2:$A$163=A37)*('All Seasons'!$L$2:$L$163=_xlfn.MAXIFS('All Seasons'!$L$2:$L$163,'All Seasons'!$A$2:$A$163,A37)),0)) -> peterbrune | F37: =INDEX('All Seasons'!$C$2:$C$163,MATCH(1,('All Seasons'!$A$2:$A$163=A37)*('All Seasons'!$L$2:$L$163=_xlfn.MINIFS('All Seasons'!$L$2:$L$163,'All Seasons'!$A$2:$A$163,A37)),0)) -> JPeters19
A38: 2023 | B38: =INDEX('All Seasons'!$C$2:$C$163,MATCH(1,('All Seasons'!$A$2:$A$163=A38)*('All Seasons'!$H$2:$H$163="Champion"),0)) -> jphn744 | C38: =INDEX('All Seasons'!$C$2:$C$163,MATCH(1,('All Seasons'!$A$2:$A$163=A38)*('All Seasons'!$G$2:$G$163=_xlfn.MAXIFS('All Seasons'!$G$2:$G$163,'All Seasons'!$A$2:$A$163,A38)),0)) -> jphn744 | D38: =INDEX('All Seasons'!$C$2:$C$163,MATCH(1,('All Seasons'!$A$2:$A$163=A38)*('All Seasons'!$B$2:$B$163=1),0)) -> jphn744 | E38: =INDEX('All Seasons'!$C$2:$C$163,MATCH(1,('All Seasons'!$A$2:$A$163=A38)*('All Seasons'!$L$2:$L$163=_xlfn.MAXIFS('All Seasons'!$L$2:$L$163,'All Seasons'!$A$2:$A$163,A38)),0)) -> jphn744 | F38: =INDEX('All Seasons'!$C$2:$C$163,MATCH(1,('All Seasons'!$A$2:$A$163=A38)*('All Seasons'!$L$2:$L$163=_xlfn.MINIFS('All Seasons'!$L$2:$L$163,'All Seasons'!$A$2:$A$163,A38)),0)) -> amenr5
... A40: 2025 | B40: =INDEX('All Seasons'!$C$2:$C$163,MATCH(1,('All Seasons'!$A$2:$A$163=A40)*('All Seasons'!$H$2:$H$163="Champion"),0)) -> thowd | C40: =INDEX('All Seasons'!$C$2:$C$163,MATCH(1,('All Seasons'!$A$2:$A$163=A40)*('All Seasons'!$G$2:$G$163=_xlfn.MAXIFS('All Seasons'!$G$2:$G$163,'All Seasons'!$A$2:$A$163,A40)),0)) -> bcorrigan30 | D40: =INDEX('All Seasons'!$C$2:$C$163,MATCH(1,('All Seasons'!$A$2:$A$163=A40)*('All Seasons'!$B$2:$B$163=1),0)) -> bcorrigan30 | E40: =INDEX('All Seasons'!$C$2:$C$163,MATCH(1,('All Seasons'!$A$2:$A$163=A40)*('All Seasons'!$L$2:$L$163=_xlfn.MAXIFS('All Seasons'!$L$2:$L$163,'All Seasons'!$A$2:$A$163,A40)),0)) -> bcorrigan30 | F40: =INDEX('All Seasons'!$C$2:$C$163,MATCH(1,('All Seasons'!$A$2:$A$163=A40)*('All Seasons'!$L$2:$L$163=_xlfn.MINIFS('All Seasons'!$L$2:$L$163,'All Seasons'!$A$2:$A$163,A40)),0)) -> Keughes
A43: MANAGER BADGES
A44: A read of each manager's career shape — not a formula output, just the story the numbers tell.
A45: Manager | B45: Badge | C45: Why
A46: jphn744 | B46: The Closer | C46: 5 titles from 10 playoff trips (50% conversion) — the best in league history at finishing the job.
A47: kdavis | B47: Iron Throne, Empty Hand | C47: Best career win% (62%) and the most playoff trips (12) of anyone, but only 2 titles (17% conversion) — the best regular-season team that can't close, including a 12-1 season that ended in 4th.
A48: bcorrigan30 | B48: Bronze Standard | C48: 6 third-place finishes across 14 seasons and zero titles — reaches the final four almost every deep run, never wins it.
...
